I'm sorry, but an uncaught exception occurred.

While running game code:
  File "game/story/introduction/hw_day_2.rpy", line 211, in script call
    call d2_dm_wicker
  File "game/story/introduction/hw_day_2.rpy", line 507, in script
    python:
  File "game/story/introduction/hw_day_2.rpy", line 508, in <module>
    if d2_t0read != True:
NameError: name 'd2_t0read' is not defined

-- Full Traceback ------------------------------------------------------------

Full traceback:
  File "game/story/introduction/hw_day_2.rpy", line 211, in script call
    call d2_dm_wicker
  File "game/story/introduction/hw_day_2.rpy", line 507, in script
    python:
  File "C:\Users\carol\Downloads\renpy-8.1.3-sdk\renpy\ast.py", line 1138, in execute
    renpy.python.py_exec_bytecode(self.code.bytecode, self.hide, store=self.store)
  File "C:\Users\carol\Downloads\renpy-8.1.3-sdk\renpy\python.py", line 1122, in py_exec_bytecode
    exec(bytecode, globals, locals)
  File "game/story/introduction/hw_day_2.rpy", line 508, in <module>
    if d2_t0read != True:
NameError: name 'd2_t0read' is not defined

Windows-10-10.0.22621 AMD64
Ren'Py 8.1.3.23091805
Production 1.0
Tue Feb 27 14:57:15 2024
